Workbook

Sheet Anleitung
A1: Preisliste für den Online-Angebotsrechner
A2: Elektrotechnik Ulshöfer GmbH · Stand: Website-Version v0.7.0 · alle Preise sind Beispielwerte
A4: Wozu dient diese Tabelle?
A5: Sie enthält alle Preise, Arbeitszeiten und Geräte, mit denen der Angebotsrechner auf der Website rechnet – in derselben Reihenfolge wie in der Online-Preisverwaltung.
A6: So gehen Sie vor
A7: 1. Tragen Sie Ihre echten Nettopreise und Stunden in die gelben Zellen mit blauer Schrift ein.
A8: 2. Alle grauen Spalten (Bruttopreis, Arbeitslohn) rechnen sich automatisch – mit Stundensatz und MwSt. aus dem Blatt „Allgemein“.
A9: 3. Senden Sie die Tabelle zurück. Wir übernehmen die Werte 1:1 in die Website. Alternativ können Sie die Preise direkt in der Online-Preisverwaltung ändern.
A10: Wie rechnet die Website?
A11: • Gerätepreis + Material (netto) + Arbeitslohn (Stunden × Stundensatz) + einmalig die Anfahrt; darauf kommt die MwSt. (Photovoltaik und Speicher: 0 % MwSt.).
A12: • Klimaanlage und Wärmepumpe: Die Website wählt automatisch das kleinste passende Gerät, bei gleicher Leistung das günstigste.
A13: • Photovoltaik: Verwendet wird das erste Modul der Liste; der Wechselrichter muss mindestens 80 % der Modulleistung erreichen.
... A18: Legende
A19: Eingabe | B19: gelbe Zelle, blaue Schrift: Ihre Werte
A20: Berechnet | B20: graue Zelle: Formel, nicht überschreiben

Sheet Allgemein
A1: Allgemein
A2: Stundensatz, MwSt., Anfahrt, Gültigkeit und KfW-Förderung. Diese Werte gelten für alle Blätter.
A4: Einstellung | B4: Wert | C4: Einheit
A5: Anfahrt (einmal pro Angebot) | B5: 45 | C5: €
A6: Stundensatz Monteur | B6: 68 | C6: €/h
A7: Preisspanne „von … bis …“ ± | B7: 0.08 | C7: %
A8: MwSt. | B8: 0.19 | C8: %
A9: Gültigkeit des Angebots | B9: 30 | C9: Tage
A11: KfW-Förderung Wärmepumpe (Programm 458)
A12: KfW-Regeln seit 21.07.2026. Der Klimageschwindigkeitsbonus sinkt auf 12 % ab 1.2.2027 und 8 % ab 1.8.2027. Die förderfähigen Kosten sinken jeweils zum 1.2. und 1.8. um 750 €.
A13: Einstellung | B13: Wert | C13: Einheit
A14: Grundförderung | B14: 0.3 | C14: %
A15: Klimageschwindigkeitsbonus | B15: 0.16 | C15: %
A16: Höchstfördersatz | B16: 0.7 | C16: %
A17: Höchstsatz bei Einkommen bis 30.000 € | B17: 0.8 | C17: %
A18: Max. förderfähige Kosten | B18: 28000 | C18: €
A20: Sichtbare Bereiche auf der Website
A21: Ausgeschaltet: Der Bereich erscheint weder im Rechner noch in der Schnellauswahl oder im Footer. Die Beschreibung unter „Leistungen“ bleibt sichtbar – mit dem Button „Beratung anfragen“.
A22: Bereich | B22: Sichtbar
A23: Wärmepumpe | B23: Ja
A24: Photovoltaik | B24: Ja
A25: Klimaanlage | B25: Ja
A26: Smart Home | B26: Ja
A27: Elektroinstallation | B27: Ja
A28: Hausgeräte (Online-Bestellung) | B28: Ja
A29: Chat-Assistent „Fragen?“ | B29: Ja

Sheet Klimaanlage
A1: Klimaanlage
A2: Gelbe Zellen ändern. Bruttopreise und Arbeitslohn werden mit Stundensatz und MwSt. aus „Allgemein“ berechnet.
A4: Single-Split-Geräte (Set Innen- + Außengerät)
A5: Die Website wählt das kleinste Gerät, das für den Raum reicht, in der vom Kunden gewählten Klasse; bei gleicher Leistung das günstigste.
A6: Aktiv | B6: Hersteller | C6: Modell | D6: Leistung (kW) | E6: Klasse | F6: Nettopreis (€) | G6: Bruttopreis (€)
A7: Ja | B7: Toshiba | C7: Seiya RAS-B10E2KVG-E / RAS-10E2AVG-E | D7: 2.5 | E7: Standard | F7: 990 | G7: =F7*(1+Allgemein!$B$8) -> 1178.1
A8: Ja | B8: Toshiba | C8: Seiya RAS-B13E2KVG-E / RAS-13E2AVG-E | D8: 3.3 | E8: Standard | F8: 1120 | G8: =F8*(1+Allgemein!$B$8) -> 1332.8
A9: Ja | B9: Toshiba | C9: Seiya RAS-B16E2KVG-E / RAS-16E2AVG-E | D9: 4.2 | E9: Standard | F9: 1390 | G9: =F9*(1+Allgemein!$B$8) -> 1654.1
A10: Ja | B10: Toshiba | C10: Seiya RAS-B18E2KVG-E / RAS-18E2AVG-E | D10: 5 | E10: Standard | F10: 1590 | G10: =F10*(1+Allgemein!$B$8) -> 1892.1
A11: Ja | B11: Toshiba | C11: Seiya RAS-B24E2KVG-E / RAS-24E2AVG-E | D11: 6.5 | E11: Standard | F11: 2090 | G11: =F11*(1+Allgemein!$B$8) -> 2487.1
A12: Ja | B12: Toshiba | C12: Shorai Curve RAS-B10P2KVSG-E | D12: 2.5 | E12: Premium | F12: 1390 | G12: =F12*(1+Allgemein!$B$8) -> 1654.1
A13: Ja | B13: Toshiba | C13: Shorai Curve RAS-B13P2KVSG-E | D13: 3.5 | E13: Premium | F13: 1550 | G13: =F13*(1+Allgemein!$B$8) -> 1844.5
A14: Ja | B14: Toshiba | C14: Shorai Curve RAS-B16P2KVSG-E | D14: 4.6 | E14: Premium | F14: 1790 | G14: =F14*(1+Allgemein!$B$8) -> 2130.1
A15: Ja | B15: Toshiba | C15: Shorai Curve RAS-B18P2KVSG-E | D15: 5 | E15: Premium | F15: 1990 | G15: =F15*(1+Allgemein!$B$8) -> 2368.1
A16: Ja | B16: Toshiba | C16: Daisekai 10 RAS-B13S4KVPG-E | D16: 3.5 | E16: Premium | F16: 2390 | G16: =F16*(1+Allgemein!$B$8) -> 2844.1
A17: Ja | B17: Daikin | C17: Sensira FTXF25D / RXF25D | D17: 2.5 | E17: Standard | F17: 1090 | G17: =F17*(1+Allgemein!$B$8) -> 1297.1
A18: Ja | B18: Daikin | C18: Sensira FTXF35D / RXF35D | D18: 3.5 | E18: Standard | F18: 1240 | G18: =F18*(1+Allgemein!$B$8) -> 1475.6
... A26: Ja | B26: Mitsubishi Electric | C26: MSZ-AY71VGK / MUZ-AY71VG | D26: 7.1 | E26: Standard | F26: 2390 | G26: =F26*(1+Allgemein!$B$8) -> 2844.1
A27: Neue Zeile: einfach unten anfügen und in die Preisverwaltung übernehmen.
A29: Multi-Split-Innengeräte
A30: Aktiv | B30: Hersteller | C30: Modell | D30: Leistung (kW) | E30: Klasse | F30: Nettopreis (€) | G30: Bruttopreis (€)
A31: Ja | B31: Toshiba | C31: Seiya RAS-B10E2KVG-E (Multi) | D31: 2.5 | E31: Standard | F31: 420 | G31: =F31*(1+Allgemein!$B$8) -> 499.8
A32: Ja | B32: Toshiba | C32: Seiya RAS-B13E2KVG-E (Multi) | D32: 3.3 | E32: Standard | F32: 470 | G32: =F32*(1+Allgemein!$B$8) -> 559.3
A33: Ja | B33: Toshiba | C33: Seiya RAS-B16E2KVG-E (Multi) | D33: 4.2 | E33: Standard | F33: 560 | G33: =F33*(1+Allgemein!$B$8) -> 666.4
A34: Ja | B34: Toshiba | C34: Shorai Curve RAS-B10P2KVSG-E (Multi) | D34: 2.5 | E34: Premium | F34: 590 | G34: =F34*(1+Allgemein!$B$8) -> 702.1
A35: Ja | B35: Toshiba | C35: Shorai Curve RAS-B13P2KVSG-E (Multi) | D35: 3.5 | E35: Premium | F35: 660 | G35: =F35*(1+Allgemein!$B$8) -> 785.4
A36: Ja | B36: Toshiba | C36: Shorai Curve RAS-B16P2KVSG-E (Multi) | D36: 4.6 | E36: Premium | F36: 760 | G36: =F36*(1+Allgemein!$B$8) -> 904.4
A37: Ja | B37: Daikin | C37: Perfera FTXM20R | D37: 2 | E37: Premium | F37: 560 | G37: =F37*(1+Allgemein!$B$8) -> 666.4
A38: Ja | B38: Daikin | C38: Perfera FTXM25R | D38: 2.5 | E38: Premium | F38: 600 | G38: =F38*(1+Allgemein!$B$8) -> 714
A39: Ja | B39: Daikin | C39: Perfera FTXM35R | D39: 3.5 | E39: Premium | F39: 680 | G39: =F39*(1+Allgemein!$B$8) -> 809.2
A40: Ja | B40: Daikin | C40: Perfera FTXM50R | D40: 5 | E40: Premium | F40: 860 | G40: =F40*(1+Allgemein!$B$8) -> 1023.4
A41: Ja | B41: Daikin | C41: Sensira FTXF25D | D41: 2.5 | E41: Standard | F41: 430 | G41: =F41*(1+Allgemein!$B$8) -> 511.7
A42: Ja | B42: Daikin | C42: Sensira FTXF35D | D42: 3.5 | E42: Standard | F42: 490 | G42: =F42*(1+Allgemein!$B$8) -> 583.1
A43: Ja | B43: Daikin | C43: Sensira FTXF50D | D43: 5 | E43: Standard | F43: 640 | G43: =F43*(1+Allgemein!$B$8) -> 761.6
A44: Neue Zeile: einfach unten anfügen und in die Preisverwaltung übernehmen.
A46: Multi-Split-Außengeräte
A47: Aktiv | B47: Hersteller | C47: Modell | D47: Anschlüsse (Stk.) | E47: Leistung (kW) | F47: Nettopreis (€) | G47: Bruttopreis (€)
A48: Ja | B48: Toshiba | C48: RAS-2M14G3AVG-E | D48: 2 | E48: 4 | F48: 1590 | G48: =F48*(1+Allgemein!$B$8) -> 1892.1
A49: Ja | B49: Toshiba | C49: RAS-3M18G3AVG-E | D49: 3 | E49: 5.2 | F49: 1990 | G49: =F49*(1+Allgemein!$B$8) -> 2368.1
A50: Ja | B50: Toshiba | C50: RAS-3M26G3AVG-E | D50: 3 | E50: 7.5 | F50: 2390 | G50: =F50*(1+Allgemein!$B$8) -> 2844.1
...

Sheet Wärmepumpe
A1: Wärmepumpe
A2: Gelbe Zellen ändern. Bruttopreise und Arbeitslohn werden mit Stundensatz und MwSt. aus „Allgemein“ berechnet.
A4: Geräte (Luft-Wasser-Wärmepumpen)
A5: Die Website wählt das kleinste Gerät, das die Heizlast deckt; der Kunde kann nach Hersteller filtern.
A6: Aktiv | B6: Hersteller | C6: Modell | D6: Leistung (kW) | E6: Nettopreis (€) | F6: Bruttopreis (€)
A7: Ja | B7: Dimplex | C7: System M Comfort Plus 4–6 kW (Split) | D7: 6 | E7: 8900 | F7: =E7*(1+Allgemein!$B$8) -> 10591
A8: Ja | B8: Dimplex | C8: LA 9S-TUR (Monoblock außen) | D8: 9 | E8: 10400 | F8: =E8*(1+Allgemein!$B$8) -> 12376
A9: Ja | B9: Dimplex | C9: LA 0712C (Monoblock außen) | D9: 12 | E9: 11900 | F9: =E9*(1+Allgemein!$B$8) -> 14161
A10: Ja | B10: Dimplex | C10: M Flex 0916HBC (Split, 9–16 kW) | D10: 16 | E10: 13400 | F10: =E10*(1+Allgemein!$B$8) -> 15946
A11: Ja | B11: Dimplex | C11: LA 1118C (Monoblock außen) | D11: 18 | E11: 14900 | F11: =E11*(1+Allgemein!$B$8) -> 17731
A12: Neue Zeile: einfach unten anfügen und in die Preisverwaltung übernehmen.
A14: Arbeitszeit (Stunden)
A15: Position | B15: Wert | C15: Einheit | D15: Arbeitslohn netto | E15: Brutto inkl. MwSt.
A16: Montage, hydraulischer Abgleich, Inbetriebnahme | B16: 30 | C16: Std. | D16: =B16*Allgemein!$B$6 -> 2040 | E16: =D16*(1+Allgemein!$B$8) -> 2427.6
A17: Demontage Ölkessel | B17: 12 | C17: Std. | D17: =B17*Allgemein!$B$6 -> 816 | E17: =D17*(1+Allgemein!$B$8) -> 971.04
A18: Demontage Gaskessel | B18: 6 | C18: Std. | D18: =B18*Allgemein!$B$6 -> 408 | E18: =D18*(1+Allgemein!$B$8) -> 485.52
A19: Demontage Nachtspeicheröfen | B19: 10 | C19: Std. | D19: =B19*Allgemein!$B$6 -> 680 | E19: =D19*(1+Allgemein!$B$8) -> 809.2
A20: Heizkörpertausch, pro Stück | B20: 2.5 | C20: Std. | D20: =B20*Allgemein!$B$6 -> 170 | E20: =D20*(1+Allgemein!$B$8) -> 202.3
A21: Zählerschrank | B21: 6 | C21: Std. | D21: =B21*Allgemein!$B$6 -> 408 | E21: =D21*(1+Allgemein!$B$8) -> 485.52
A23: Material (netto)
A24: Position | B24: Wert | C24: Einheit | D24: Arbeitslohn netto | E24: Brutto inkl. MwSt.
A25: Hydraulikpaket (Puffer, Warmwasserspeicher, Anschlüsse) | B25: 4200 | C25: € | E25: =B25*(1+Allgemein!$B$8) -> 4998
A26: Entsorgung Heizöl und Tankreinigung | B26: 900 | C26: € | E26: =B26*(1+Allgemein!$B$8) -> 1071
A27: Entsorgung Gaskessel | B27: 150 | C27: € | E27: =B27*(1+Allgemein!$B$8) -> 178.5
A28: Entsorgung Nachtspeicheröfen | B28: 350 | C28: € | E28: =B28*(1+Allgemein!$B$8) -> 416.5
A29: Niedertemperatur-Heizkörper | B29: 380 | C29: € | E29: =B29*(1+Allgemein!$B$8) -> 452.2
A30: Zählerplatz Wärmepumpe | B30: 650 | C30: € | E30: =B30*(1+Allgemein!$B$8) -> 773.5
A32: Berechnung
A33: Position | B33: Wert | C33: Einheit | D33: Arbeitslohn netto | E33: Brutto inkl. MwSt.
A34: Warmwasser: Zusatzleistung pro Person | B34: 0.25 | C34: kW

Sheet Photovoltaik
A1: Photovoltaik
A2: Gelbe Zellen ändern. Bruttopreise und Arbeitslohn werden mit Stundensatz und MwSt. aus „Allgemein“ berechnet.
A4: Module
A5: Die Website verwendet das erste Modul der Liste. Mit ↑ schieben Sie ein Modul nach oben.
A6: Aktiv | B6: Hersteller | C6: Modell | D6: Leistung (Wp) | E6: Preis pro Modul (€) | F6: Bruttopreis (€)
A7: Ja | B7: Aiko | C7: Neostar 2P 450 Wp Glas-Glas | D7: 450 | E7: 118 | F7: =E7*(1+Allgemein!$B$8) -> 140.42
A8: Ja | B8: Meyer Burger | C8: Glass 400 Wp | D8: 400 | E8: 175 | F8: =E8*(1+Allgemein!$B$8) -> 208.25
A9: Neue Zeile: einfach unten anfügen und in die Preisverwaltung übernehmen.
A11: Wechselrichter
A12: Gewählt wird der kleinste Wechselrichter mit mindestens 80 % der Modulleistung.
A13: Aktiv | B13: Hersteller | C13: Modell | D13: Leistung (kW) | E13: Nettopreis (€) | F13: Bruttopreis (€)
A14: Ja | B14: Fronius | C14: Primo GEN24 4.0 Plus | D14: 4 | E14: 1750 | F14: =E14*(1+Allgemein!$B$8) -> 2082.5
A15: Ja | B15: Fronius | C15: Primo GEN24 6.0 Plus | D15: 6 | E15: 2050 | F15: =E15*(1+Allgemein!$B$8) -> 2439.5
A16: Ja | B16: Fronius | C16: Symo GEN24 8.0 Plus | D16: 8 | E16: 2550 | F16: =E16*(1+Allgemein!$B$8) -> 3034.5
A17: Ja | B17: Fronius | C17: Symo GEN24 10.0 Plus | D17: 10 | E17: 2850 | F17: =E17*(1+Allgemein!$B$8) -> 3391.5
A18: Ja | B18: Fronius | C18: Tauro 15-3-P | D18: 15 | E18: 3600 | F18: =E18*(1+Allgemein!$B$8) -> 4284
A19: Neue Zeile: einfach unten anfügen und in die Preisverwaltung übernehmen.
A21: Speicher
A22: Der Kunde wählt einen dieser Speicher oder keinen.
A23: Aktiv | B23: Hersteller | C23: Modell | D23: Kapazität (kWh) | E23: Nettopreis (€) | F23: Bruttopreis (€)
A24: Ja | B24: BYD | C24: Battery-Box Premium HVS 5.1 | D24: 5.1 | E24: 2950 | F24: =E24*(1+Allgemein!$B$8) -> 3510.5
A25: Ja | B25: BYD | C25: Battery-Box Premium HVS 7.7 | D25: 7.7 | E25: 4050 | F25: =E25*(1+Allgemein!$B$8) -> 4819.5
A26: Ja | B26: BYD | C26: Battery-Box Premium HVS 10.2 | D26: 10.2 | E26: 5150 | F26: =E26*(1+Allgemein!$B$8) -> 6128.5
A27: Neue Zeile: einfach unten anfügen und in die Preisverwaltung übernehmen.
A29: Wallbox
A30: Die Wallbox-Modelle werden im Reiter „Elektroinstallation“ gepflegt (gemeinsame Liste).
A31: Position | B31: Wert | C31: Einheit | D31: Arbeitslohn netto | E31: Brutto inkl. MwSt.
A32: Montagestunden Wallbox mit PV | B32: 5 | C32: Std. | D32: =B32*Allgemein!$B$6 -> 340 | E32: =D32*(1+Allgemein!$B$8) -> 404.6
A34: Arbeitszeit (Stunden)
A35: Position | B35: Wert | C35: Einheit | D35: Arbeitslohn netto | E35: Brutto inkl. MwSt.
A36: Montage: Grundpauschale | B36: 8 | C36: Std. | D36: =B36*Allgemein!$B$6 -> 544 | E36: =D36*(1+Allgemein!$B$8) -> 647.36
A37: … je Modul | B37: 0.6 | C37: Std. | D37: =B37*Allgemein!$B$6 -> 40.8 | E37: =D37*(1+Allgemein!$B$8) -> 48.552
A38: Montage Speicher | B38: 4 | C38: Std. | D38: =B38*Allgemein!$B$6 -> 272 | E38: =D38*(1+Allgemein!$B$8) -> 323.68
A39: Notstromfunktion | B39: 4 | C39: Std. | D39: =B39*Allgemein!$B$6 -> 272 | E39: =D39*(1+Allgemein!$B$8) -> 323.68
A41: Material (netto)
A42: Position | B42: Wert | C42: Einheit | D42: Arbeitslohn netto | E42: Brutto inkl. MwSt.
A43: Unterkonstruktion, pro Modul | B43: 48 | C43: € | E43: =B43*(1+Allgemein!$B$8) -> 57.12
A44: DC/AC-Verkabelung, Schutzeinrichtungen, Kleinmaterial | B44: 480 | C44: € | E44: =B44*(1+Allgemein!$B$8) -> 571.2
A45: Gerüst / Absturzsicherung | B45: 650 | C45: € | E45: =B45*(1+Allgemein!$B$8) -> 773.5
A46: Anpassung Zählerschrank | B46: 450 | C46: € | E46: =B46*(1+Allgemein!$B$8) -> 535.5
...

Sheet Smart Home
A1: Smart Home
A2: Gelbe Zellen ändern. Bruttopreise und Arbeitslohn werden mit Stundensatz und MwSt. aus „Allgemein“ berechnet.
A4: System Loxone
A5: Position | B5: Wert | C5: Einheit | D5: Arbeitslohn netto | E5: Brutto inkl. MwSt.
A6: Bezeichnung im Angebot | B6: Loxone (Miniserver, Tree/Air)
A7: Zentrale / Grundausstattung – Material | B7: 900 | C7: € | E7: =B7*(1+Allgemein!$B$8) -> 1071
A8: Zentrale / Grundausstattung – Stunden | B8: 12 | C8: Std. | D8: =B8*Allgemein!$B$6 -> 816 | E8: =D8*(1+Allgemein!$B$8) -> 971.04
A9: Licht, pro Raum – Material | B9: 160 | C9: € | E9: =B9*(1+Allgemein!$B$8) -> 190.4
A10: Licht, pro Raum – Stunden | B10: 1.5 | C10: Std. | D10: =B10*Allgemein!$B$6 -> 102 | E10: =D10*(1+Allgemein!$B$8) -> 121.38
A11: Heizung, pro Raum – Material | B11: 120 | C11: € | E11: =B11*(1+Allgemein!$B$8) -> 142.8
A12: Heizung, pro Raum – Stunden | B12: 1 | C12: Std. | D12: =B12*Allgemein!$B$6 -> 68 | E12: =D12*(1+Allgemein!$B$8) -> 80.92
A13: Rollladen, pro Stück – Material | B13: 140 | C13: € | E13: =B13*(1+Allgemein!$B$8) -> 166.6
A14: Rollladen, pro Stück – Stunden | B14: 1.5 | C14: Std. | D14: =B14*Allgemein!$B$6 -> 102 | E14: =D14*(1+Allgemein!$B$8) -> 121.38
A15: Sicherheitspaket – Material | B15: 600 | C15: € | E15: =B15*(1+Allgemein!$B$8) -> 714
A16: Sicherheitspaket – Stunden | B16: 5 | C16: Std. | D16: =B16*Allgemein!$B$6 -> 340 | E16: =D16*(1+Allgemein!$B$8) -> 404.6
A18: System Funk
A19: Position | B19: Wert | C19: Einheit | D19: Arbeitslohn netto | E19: Brutto inkl. MwSt.
A20: Bezeichnung im Angebot | B20: Homematic IP (Funk)
A21: Zentrale / Grundausstattung – Material | B21: 180 | C21: € | E21: =B21*(1+Allgemein!$B$8) -> 214.2
A22: Zentrale / Grundausstattung – Stunden | B22: 3 | C22: Std. | D22: =B22*Allgemein!$B$6 -> 204 | E22: =D22*(1+Allgemein!$B$8) -> 242.76
A23: Licht, pro Raum – Material | B23: 75 | C23: € | E23: =B23*(1+Allgemein!$B$8) -> 89.25
A24: Licht, pro Raum – Stunden | B24: 1.25 | C24: Std. | D24: =B24*Allgemein!$B$6 -> 85 | E24: =D24*(1+Allgemein!$B$8) -> 101.15
A25: Heizung, pro Raum – Material | B25: 65 | C25: € | E25: =B25*(1+Allgemein!$B$8) -> 77.35
A26: Heizung, pro Raum – Stunden | B26: 0.75 | C26: Std. | D26: =B26*Allgemein!$B$6 -> 51 | E26: =D26*(1+Allgemein!$B$8) -> 60.69
A27: Rollladen, pro Stück – Material | B27: 70 | C27: € | E27: =B27*(1+Allgemein!$B$8) -> 83.3
A28: Rollladen, pro Stück – Stunden | B28: 1.25 | C28: Std. | D28: =B28*Allgemein!$B$6 -> 85 | E28: =D28*(1+Allgemein!$B$8) -> 101.15
A29: Sicherheitspaket – Material | B29: 450 | C29: € | E29: =B29*(1+Allgemein!$B$8) -> 535.5
A30: Sicherheitspaket – Stunden | B30: 4 | C30: Std. | D30: =B30*Allgemein!$B$6 -> 272 | E30: =D30*(1+Allgemein!$B$8) -> 323.68
A32: System KNX
A33: Position | B33: Wert | C33: Einheit | D33: Arbeitslohn netto | E33: Brutto inkl. MwSt.
A34: Bezeichnung im Angebot | B34: KNX (Gira / ABB)
A35: Zentrale / Grundausstattung – Material | B35: 1300 | C35: € | E35: =B35*(1+Allgemein!$B$8) -> 1547
A36: Zentrale / Grundausstattung – Stunden | B36: 14 | C36: Std. | D36: =B36*Allgemein!$B$6 -> 952 | E36: =D36*(1+Allgemein!$B$8) -> 1132.88
A37: Licht, pro Raum – Material | B37: 180 | C37: € | E37: =B37*(1+Allgemein!$B$8) -> 214.2
A38: Licht, pro Raum – Stunden | B38: 2 | C38: Std. | D38: =B38*Allgemein!$B$6 -> 136 | E38: =D38*(1+Allgemein!$B$8) -> 161.84
A39: Heizung, pro Raum – Material | B39: 140 | C39: € | E39: =B39*(1+Allgemein!$B$8) -> 166.6
A40: Heizung, pro Raum – Stunden | B40: 1.5 | C40: Std. | D40: =B40*Allgemein!$B$6 -> 102 | E40: =D40*(1+Allgemein!$B$8) -> 121.38
A41: Rollladen, pro Stück – Material | B41: 150 | C41: € | E41: =B41*(1+Allgemein!$B$8) -> 178.5
A42: Rollladen, pro Stück – Stunden | B42: 1.75 | C42: Std. | D42: =B42*Allgemein!$B$6 -> 119 | E42: =D42*(1+Allgemein!$B$8) -> 141.61
A43: Sicherheitspaket – Material | B43: 700 | C43: € | E43: =B43*(1+Allgemein!$B$8) -> 833
...

Sheet Hausgeräte
A1: Hausgeräte
A2: Gelbe Zellen ändern. Bruttopreise und Arbeitslohn werden mit Stundensatz und MwSt. aus „Allgemein“ berechnet.
A4: Partner / Marken
A5: Ausgeschaltete Marken verschwinden mitsamt ihren Produkten aus der Online-Bestellung.
A6: Aktiv | B6: Name
A7: Ja | B7: Siemens Hausgeräte
A8: Ja | B8: Miele
A9: Ja | B9: Liebherr
A10: Neue Zeile: einfach unten anfügen und in die Preisverwaltung übernehmen.
A12: Produkte
A13: Preise BRUTTO (inkl. MwSt.) wie im Laden. Bild am besten quadratisch mit weißem Hintergrund; es wird automatisch verkleinert.
A14: Aktiv | B14: Hersteller | C14: Kategorie | D14: Modell | E14: Kurzbeschreibung | F14: Bruttopreis (€) | G14: Anschluss/Montage brutto (€)
A15: Ja | B15: Siemens Hausgeräte | C15: Waschmaschine | D15: iQ300 Waschmaschine 8 kg | E15: Beispielprodukt – Ausstattung und Preis folgen | F15: 599 | G15: 49
A16: Ja | B16: Siemens Hausgeräte | C16: Waschmaschine | D16: iQ500 Waschmaschine 9 kg | E16: Beispielprodukt – Ausstattung und Preis folgen | F16: 799 | G16: 49
A17: Ja | B17: Siemens Hausgeräte | C17: Wäschetrockner | D17: iQ500 Wärmepumpentrockner 8 kg | E17: Beispielprodukt – Ausstattung und Preis folgen | F17: 849 | G17: 39
A18: Ja | B18: Siemens Hausgeräte | C18: Geschirrspüler | D18: iQ300 Einbau-Geschirrspüler 60 cm | E18: Beispielprodukt – Ausstattung und Preis folgen | F18: 649 | G18: 149
A19: Ja | B19: Siemens Hausgeräte | C19: Backofen & Herd | D19: iQ500 Einbau-Backofen | E19: Beispielprodukt – Ausstattung und Preis folgen | F19: 699 | G19: 129
A20: Ja | B20: Siemens Hausgeräte | C20: Kühlen & Gefrieren | D20: iQ300 Kühl-Gefrier-Kombination | E20: Beispielprodukt – Ausstattung und Preis folgen | F20: 749 | G20: 39
A21: Ja | B21: Miele | C21: Waschmaschine | D21: Waschmaschine W1 (Beispiel) | E21: Beispielprodukt – Ausstattung und Preis folgen | F21: 1199 | G21: 49
A22: Ja | B22: Liebherr | C22: Kühlen & Gefrieren | D22: Kühl-Gefrier-Kombination (Beispiel) | E22: Beispielprodukt – Ausstattung und Preis folgen | F22: 999 | G22: 39
A23: Neue Zeile: einfach unten anfügen und in die Preisverwaltung übernehmen.
A25: Leistungen
A26: Position | B26: Wert | C26: Einheit | D26: Arbeitslohn netto | E26: Brutto inkl. MwSt.
A27: Lieferung pro Gerät (brutto) | B27: 39 | C27: €
A28: Altgerät-Mitnahme pro Gerät (brutto) | B28: 25 | C28: €
A29: Lieferzeit (Text für den Kunden) | B29: In der Regel 3–10 Werktage, Liefertermin nach Absprache.

Sheet Elektroinstallation
A1: Elektroinstallation
A2: Gelbe Zellen ändern. Bruttopreise und Arbeitslohn werden mit Stundensatz und MwSt. aus „Allgemein“ berechnet.
A4: Installation pro m²
A5: Position | B5: Wert | C5: Einheit | D5: Arbeitslohn netto | E5: Brutto inkl. MwSt.
A6: Neubau – Material pro m² | B6: 42 | C6: € | E6: =B6*(1+Allgemein!$B$8) -> 49.98
A7: Neubau – Stunden pro m² | B7: 0.75 | C7: Std. | D7: =B7*Allgemein!$B$6 -> 51 | E7: =D7*(1+Allgemein!$B$8) -> 60.69
A8: Komplettsanierung – Material pro m² | B8: 52 | C8: € | E8: =B8*(1+Allgemein!$B$8) -> 61.88
A9: Komplettsanierung – Stunden pro m² | B9: 1.2 | C9: Std. | D9: =B9*Allgemein!$B$6 -> 81.6 | E9: =D9*(1+Allgemein!$B$8) -> 97.104
A10: Teilsanierung – Material pro m² | B10: 30 | C10: € | E10: =B10*(1+Allgemein!$B$8) -> 35.7
A11: Teilsanierung – Stunden pro m² | B11: 0.6 | C11: Std. | D11: =B11*Allgemein!$B$6 -> 40.8 | E11: =D11*(1+Allgemein!$B$8) -> 48.552
A13: Einzelpositionen
A14: Position | B14: Wert | C14: Einheit | D14: Arbeitslohn netto | E14: Brutto inkl. MwSt.
A15: Neuer Zählerschrank – Material | B15: 1650 | C15: € | E15: =B15*(1+Allgemein!$B$8) -> 1963.5
A16: Neuer Zählerschrank – Stunden | B16: 18 | C16: Std. | D16: =B16*Allgemein!$B$6 -> 1224 | E16: =D16*(1+Allgemein!$B$8) -> 1456.56
A17: Netzwerkdose – Material | B17: 55 | C17: € | E17: =B17*(1+Allgemein!$B$8) -> 65.45
A18: Netzwerkdose – Stunden | B18: 1.4 | C18: Std. | D18: =B18*Allgemein!$B$6 -> 95.2 | E18: =D18*(1+Allgemein!$B$8) -> 113.288
A19: Überspannungsschutz – Material | B19: 330 | C19: € | E19: =B19*(1+Allgemein!$B$8) -> 392.7
A20: Überspannungsschutz – Stunden | B20: 2.5 | C20: Std. | D20: =B20*Allgemein!$B$6 -> 170 | E20: =D20*(1+Allgemein!$B$8) -> 202.3
A21: E-CHECK – Material | B21: 0 | C21: € | E21: =B21*(1+Allgemein!$B$8) -> 0
A22: E-CHECK – Stunden | B22: 2.75 | C22: Std. | D22: =B22*Allgemein!$B$6 -> 187 | E22: =D22*(1+Allgemein!$B$8) -> 222.53
A24: Wallboxen (für Elektroinstallation und Photovoltaik)
A25: Der Kunde wählt die Wallbox im Rechner. Angeboten werden nur aktive Modelle.
A26: Aktiv | B26: Hersteller | C26: Modell | D26: Leistung (kW) | E26: Nettopreis (€) | F26: Bruttopreis (€)
A27: Ja | B27: Fronius | C27: Wattpilot Home 11 J | D27: 11 | E27: 890 | F27: =E27*(1+Allgemein!$B$8) -> 1059.1
A28: Ja | B28: ABL | C28: eMH1 11 kW | D28: 11 | E28: 720 | F28: =E28*(1+Allgemein!$B$8) -> 856.8
A29: Ja | B29: Mennekes | C29: AMTRON Compact 2.0s 11 | D29: 11 | E29: 990 | F29: =E29*(1+Allgemein!$B$8) -> 1178.1
A30: Ja | B30: Heidelberg | C30: Energy Control | D30: 11 | E30: 650 | F30: =E30*(1+Allgemein!$B$8) -> 773.5
A31: Neue Zeile: einfach unten anfügen und in die Preisverwaltung übernehmen.
A33: Montage Wallbox
A34: Position | B34: Wert | C34: Einheit | D34: Arbeitslohn netto | E34: Brutto inkl. MwSt.
A35: Montagestunden (inkl. Zuleitung und Anmeldung) | B35: 7 | C35: Std. | D35: =B35*Allgemein!$B$6 -> 476 | E35: =D35*(1+Allgemein!$B$8) -> 566.44

Sheet Partner
A1: Partner
A2: Systempartner (auf der Website hervorgehoben), danach weitere Marken
A4: Partner | B4: Bereich | C4: Art | D4: Website
A5: Fronius | B5: Photovoltaik (Service Partner Plus, TÜV) | C5: Systempartner | D5: http://www.fronius.com/
A6: Dimplex | B6: Wärmepumpen | C6: Systempartner | D6: https://www.dimplex.eu/de-de
A7: Toshiba | B7: Klimaanlagen | C7: Systempartner | D7: https://www.toshiba-aircondition.com/de/
A8: Loxone | B8: Smart Home / Gebäudeautomation | C8: Systempartner | D8: https://www.loxone.com/dede/
A9: e-masters | B9: Verbund von Elektrofachbetrieben | C9: Systempartner | D9: https://www.e-masters.de/
A10: ABN | B10: Installation / Fachgeschäft | C10: Marke | D10: https://www.abn-electro.com/
A11: Braun | B11: Installation / Fachgeschäft | C11: Marke | D11: https://www.braun.com/
A12: Gira | B12: Installation / Fachgeschäft | C12: Marke | D12: https://www.gira.de/
A13: Hager | B13: Installation / Fachgeschäft | C13: Marke | D13: https://hager.com/de
A14: Jung | B14: Installation / Fachgeschäft | C14: Marke | D14: https://www.jung.de/
A15: Krups | B15: Installation / Fachgeschäft | C15: Marke | D15: https://www.krups.de/
... A20: STR Elektronik | B20: Installation / Fachgeschäft | C20: Marke | D20: https://www.str-elektronik.de/
